Workbook

Sheet فهرست استانداردها
A1: ردیف | B1: خانواده | C1: استاندارد | D1: نام فارسی | E1: نام انگلیسی | F1: دسته | G1: اولویت | H1: استاندارد جاری | I1: معادل‌ها | J1: محدودهٔ سایز | K1: تعداد سایز | L1: کلاس / جنس | M1: نام بازاری | N1: تعداد کالای کددار | O1: عکس محصول | P1: نقشهٔ فنی | Q1: تصویر فهرست کاتالوگ
A2: 1 | B2: DIN | C2: DIN 1 | D2: پین مخروطی | E2: Taper Pins | F2: پین | G2: 2 | H2: DIN EN 22339 | I2: ISO 2339، CSN 022153، PN 85020، UNI 7283، EU 22339 | J2: 2 – 16 | K2: 9 | L2: فولاد ساده یا سخت‌کاری‌شده، استیل A1، استیل A2 | M2: پین مخروطی ساده با نسبت مخروطی 1:50 | N2: 0 | O2: دارد | P2: دارد | Q2: دارد
A3: 2 | B3: DIN | C3: DIN 7 | D3: پین استوانه‌ای (داول) | E3: Parallel pins (dowel pins) | F3: پین | G3: 2 | H3: DIN EN ISO 2338 | I3: ISO 2338، CSN 022150، PN 85021، UNI 1707 | J3: 1 – 20 | K3: 14 | L3: فولاد ساده یا سخت‌کاری‌شده، استیل A1، استیل A2 | M3: پین استوانه‌ای ساده دقیق، پین موازی بدون رزوه | N3: 0 | O3: دارد | P3: دارد | Q3: دارد
A4: 3 | B4: DIN | C4: DIN 39 | D4: دستگیرهٔ ثابت | E4: Fixed handles | F4: سایر اتصالات و یراق | G4: 3 | H4: DIN 39 | J4: M6 – M16 | K4: 5 | N4: 5 | O4: دارد | P4: دارد | Q4: دارد
A5: 4 | B5: DIN | C5: DIN 84 | D5: پیچ دوسو سر استوانه‌ای | E5: Slotted cheese head screws | F5: پیچ دوسو و چهارسو | G5: 1 | H5: DIN EN ISO 1207 | I5: ISO 1207، CSN 021131، PN 82215، UNI 6107 | J5: M1.6 – M10 | K5: 10 | L5: فولاد 4.8، فولاد 5.8، استیل A2-70، استیل A4-70 | N5: 127 | O5: دارد | P5: دارد | Q5: دارد
A6: 5 | B6: DIN | C6: DIN 85 | D6: پیچ دوسو سر عدسی | E6: Slotted pan head screws | F6: پیچ دوسو و چهارسو | G6: 2 | H6: DIN EN ISO 1580 | I6: ISO 1580، CSN 021137، PN 82219، UNI 6108 | J6: M1.6 – M10 | K6: 9 | L6: فولاد 4.8، فولاد 5.8، استیل A2-70، استیل A4-70 | N6: 117 | O6: دارد | P6: دارد | Q6: دارد
A7: 6 | B7: DIN | C7: DIN 93 | D7: واشر زبانه‌دار (قفلی) | E7: Tab washers with long tab | F7: واشر | G7: 3 | I7: CSN 021751، PN 82021، UNI 6600 | J7: M4 – M39 | K7: 17 | L7: فولاد کربنی گالوانیزه، استیل A2، استیل A4 | M7: واشر قفلی زبانه‌دار یکطرفه، واشر خاردار خم شونره | N7: 17 | O7: دارد | P7: دارد | Q7: دارد
A8: 7 | B8: DIN | C8: DIN 94 | D8: اشپیل (پین دوشاخه) | E8: Split pins | F8: پین | G8: 1 | H8: DIN EN ISO 1234 | I8: ISO 1234، CSN 021781، PN 82001، UNI 1336 | J8: 0.6 – 20 | K8: 16 | L8: فولاد کربنی ساده یا گالوانیزه، استیل A2، استیل A4 | M8: پین اشپیل، اشپیل شکاف‌دار | N8: 0 | O8: دارد | P8: دارد | Q8: دارد
A9: 8 | B9: DIN | C9: DIN 95 | D9: پیچ چوب دوسو سرخزینه عدسی | E9: Slotted oval head wood screws | F9: پیچ خودکار، سرمته و چوب | G9: 3 | H9: DIN 95 | I9: CSN 021815، PN 82504، UNI 703 | J9: 2.5 – 6 | K9: 7 | L9: فولاد، استیل A2، استیل A4 | N9: 0 | O9: دارد | P9: دارد | Q9: دارد
A10: 9 | B10: DIN | C10: DIN 96 | D10: پیچ چوب دوسو سرگرد | E10: Slotted Round Head Wood Screws | F10: پیچ خودکار، سرمته و چوب | G10: 3 | H10: DIN 96 | I10: CSN 021812، PN 82505، UNI 701 | J10: 2 – 8 | K10: 10 | L10: فولاد، استیل A2، استیل A4 | N10: 0 | O10: دارد | P10: دارد | Q10: دارد
A11: 10 | B11: DIN | C11: DIN 97 | D11: پیچ چوب دوسو سرخزینه | E11: Slotted countersunk head wood screws | F11: پیچ خودکار، سرمته و چوب | G11: 1 | H11: DIN 97 | I11: CSN 021814، PN 82503، UNI 702 | J11: 2 – 8 | K11: 10 | L11: فولاد، استیل A2، استیل A4 | N11: 0 | O11: دارد | P11: دارد | Q11: دارد
A12: 11 | B12: DIN | C12: DIN 98 | D12: دستگیرهٔ گردان | E12: Revolving handles | F12: سایر اتصالات و یراق | G12: 3 | H12: DIN 98 | J12: 16 – 36 | K12: 5 | L12: فولاد کربنی دسته با جنس پلاستیک یا باکالیت | M12: دسته استوانه‌ای چرخان مخصوص فلکه واهرم دستگاه | N12: 0 | O12: دارد | P12: دارد | Q12: دارد
A13: 12 | B13: DIN | C13: DIN 99 | D13: اهرم کلمپ | E13: Clamping Levers | F13: سایر اتصالات و یراق | G13: 3 | H13: DIN 99 | J13: M5 – M24 | K13: 8 | L13: فولاد کربنی، استیل (فولاد ضدزنگ)، پلاستیک، باکالیت | M13: مهره دستگیره‌ای، دسته ثابت ماشین الات | N13: 8 | O13: دارد | P13: دارد | Q13: دارد
A14: 13 | B14: DIN | C14: DIN 125 A | D14: واشر تخت | E14: Plain washers, Form A | F14: واشر | G14: 1 | H14: DIN 125-1, 125-2 | I14: ISO 7089، CSN 021702، PN 82006، UNI 6592 | J14: M3 – M24 | K14: 10 | L14: فولاد کربنی گالوانیزه، استیل A2، استیل A4 | N14: 30 | O14: دارد | P14: دارد | Q14: دارد
A15: 14 | B15: DIN | C15: DIN 125 B | D15: واشر تخت فرم B (پخ‌دار) | E15: Plain washers, chamfered, Form B | F15: واشر | G15: 1 | H15: DIN EN ISO 7090 | I15: ISO 7090، CSN 021702، PN 82006، UNI 1751 | J15: M5 – M160 | K15: 52 | L15: فولاد کربنی گالوانیزه، استیل A2، استیل A4 | N15: 52 | O15: دارد | P15: دارد | Q15: دارد
A16: 15 | B16: DIN | C16: DIN 126 | D16: واشر تخت (کلاس C) | E16: Plain washers, product grade C | F16: واشر | G16: 2 | H16: DIN EN ISO 7091 | I16: ISO 7091، CSN 021721، PN 82005، UNI 6593 | J16: 1.6 – 64 | K16: 19 | L16: فولاد کربنی گالوانیزه، استیل A2، استیل A4 | N16: 19 | O16: دارد | P16: دارد | Q16: دارد
A17: 16 | B17: DIN | C17: DIN 127 A | D17: واشر فنری فرم A | E17: Spring lock washers, Form A | F17: واشر | G17: 1 | I17: CSN 021741، UNI 1751 | J17: M3 – M100 | K17: 31 | L17: فولاد فنری، استیل فنری، استیل A2، استیل A4 | N17: 31 | O17: دارد | P17: دارد | Q17: دارد
A18: 17 | B18: DIN | C18: DIN 127 B | D18: واشر فنری | E18: Spring lock washers, Form B | F18: واشر | G18: 1 | I18: CSN 021741، UNI 1751 | J18: M4 – M20 | K18: 8 | L18: فولاد فنری، استیل فنری، استیل A2، استیل A4 | N18: 32 | O18: دارد | P18: دارد | Q18: دارد
A19: 18 | B19: DIN | C19: DIN 128 A | D19: واشر فنری خمیده | E19: Curved spring lock washers, Form A | F19: واشر | G19: 2 | I19: CSN 021731، UNI 8839 | J19: M2 – M36 | K19: 20 | L19: فولاد فنری، استیل فنری، استیل A2، استیل A4 | N19: 20 | O19: دارد | P19: دارد | Q19: دارد
A20: 19 | B20: DIN | C20: DIN 128 B | D20: واشر فنری موجی | E20: Wave spring lock washers, Form B | F20: واشر | G20: 2 | I20: CSN 021731، UNI 8839 | J20: M4 – M16 | K20: 7 | L20: فولاد فنری، استیل فنری، استیل A2، استیل A4 | N20: 7 | O20: دارد | P20: دارد | Q20: دارد
A21: 20 | B21: DIN | C21: DIN 134 | D21: واشر تخت پهن | E21: Plain washers, large | F21: واشر | G21: 2 | H21: Withdrawn | J21: M3 – M20 | K21: 11 | L21: فولاد کربنی، استیل A2، استیل A4 | N21: 11 | O21: دارد | P21: دارد | Q21: دارد
A22: 21 | B22: DIN | C22: DIN 137 A | D22: واشر فنری خمیده فرم A | E22: Curved spring washers, Form A | F22: واشر | G22: 2 | I22: CSN 021733، UNI 8840A | J22: 3.2 – 37 | K22: 19 | L22: فولاد فنری، استیل فنری، استیل A2، استیل A4 | M22: واشر تخت فنری موجی | N22: 19 | O22: دارد | P22: دارد | Q22: دارد
A23: 22 | B23: DIN | C23: DIN 137 B | D23: واشر فنری موجی فرم B | E23: Wave spring washers, Form B | F23: واشر | G23: 2 | I23: CSN 021733، UNI 8840B | J23: M3 – M36 | K23: 19 | L23: فولاد فنری، استیل فنری، استیل A2، استیل A4 | M23: واشر تخت فنری موجی | N23: 19 | O23: دارد | P23: دارد | Q23: دارد
A24: 23 | B24: DIN | C24: DIN 186 | D24: پیچ سر T با گردن چهارگوش | E24: T-Head bolts with square neck Head | F24: پیچ سرخاص و کالسکه | G24: 3 | H24: DIN 186 | I24: CSN 021343، PN 82418 | J24: M6 – M48 | K24: 11 | L24: فولاد 4.6، فولاد 5.6، فولاد 8.8، استیل A2-70، استیل A4-70 | M24: پیچ تی چهارخار | N24: 87 | O24: دارد | P24: دارد | Q24: دارد
A25: 24 | B25: DIN | C25: DIN 188 | D25: پیچ سر T زائده‌دار | E25: T-head bolts with double nib | F25: پیچ سرخاص و کالسکه | G25: 3 | H25: DIN 188 | I25: CSN 021343، PN 82418 | J25: M8 – M80X6 | K25: 14 | L25: فولاد 4.6، فولاد 5.6، فولاد 8.8، استیل A2-70، استیل A4-70 | M25: پیچ تی دوطرفه | N25: 127 | O25: دارد | P25: دارد | Q25: دارد
A26: 25 | B26: DIN | C26: DIN 258 | D26: پین مخروطی با رزوهٔ خارجی | E26: Taper pins with external thread | F26: پین | G26: 3 | H26: DIN 258 | I26: ISO 8737، CSN 022154، EU 28738 | J26: 5 – 20 | K26: 7 | L26: فولاد فنری سخت‌کاری‌شده، استیل A2 | N26: 0 | O26: دارد | P26: دارد | Q26: دارد
A27: 26 | B27: DIN | C27: DIN 261 | D27: پیچ سر T | E27: T-head bolts | F27: پیچ سرخاص و کالسکه | G27: 3 | H27: DIN 261 | I27: PN 82424 | J27: M8 – M100X6 | K27: 16 | L27: فولاد 4.6، فولاد 5.6، فولاد 8.8، استیل A2-70، استیل A4-70 | M27: پیچ تی | N27: 186 | O27: دارد | P27: دارد | Q27: دارد
A28: 27 | B28: DIN | C28: DIN 314 | D28: مهره پروانه‌ای | E28: Wing nuts with edged wings | F28: مهره | G28: 2 | H28: DIN 314 | J28: M4 – M12 | K28: 6 | L28: فولاد گالوانیزه، استیل A2-70، استیل A4-70 | M28: مهره خروسکی | N28: 6 | O28: دارد | P28: دارد | Q28: دارد
A29: 28 | B29: DIN | C29: DIN 315 A | D29: مهره پروانه‌ای (بال چهارگوش) | E29: Wing nuts, rectangular wings | F29: مهره | G29: 2 | H29: DIN 315 A | I29: CSN 021665، UNI 5448 | J29: M3 – M20 | K29: 11 | L29: فولاد گالوانیزه، استیل A2-70، استیل A4-70 | M29: مهره خروسکی | N29: 11 | O29: دارد | P29: دارد | Q29: دارد
A30: 29 | B30: DIN | C30: DIN 315 D | D30: مهره پروانه‌ای (بال گرد) | E30: Wing nuts, rounded wings | F30: مهره | G30: 2 | H30: DIN 315 | I30: CSN 021665، UNI 5448 | J30: M4 – M24 | K30: 9 | L30: فولاد گالوانیزه، استیل A2-70، استیل A4-70 | M30: مهره خروسکی | N30: 9 | O30: دارد | P30: دارد | Q30: دارد
A31: 30 | B31: DIN | C31: DIN 316 A | D31: پیچ پروانه‌ای (بال چهارگوش) | E31: Wing screws, rectangular wings | F31: پیچ سرخاص و کالسکه | G31: 2 | H31: DIN 316A | I31: CSN 021365، UNI 5449 | J31: M3 – M12 | K31: 7 | L31: فولاد، استیل A2، استیل A4 | M31: پیچ خروسکی | N31: 65 | O31: دارد | P31: دارد | Q31: دارد
A32: 31 | B32: DIN | C32: DIN 316 D | D32: پیچ پروانه‌ای (بال گرد) | E32: Wing screws, rounded wings | F32: پیچ سرخاص و کالسکه | G32: 2 | H32: DIN 316 | I32: CSN 021365 | J32: M4 – M24 | K32: 9 | L32: فولاد، استیل A2، استیل A4 | M32: پیچ خروسکی | N32: 72 | O32: دارد | P32: دارد | Q32: دارد
A33: 32 | B33: DIN | C33: DIN 319 | D33: دستگیرهٔ گوی | E33: Ball knobs | F33: سایر اتصالات و یراق | G33: 3 | H33: DIN 319 | J33: 12 – 50×20 | K33: 21 | L33: باکالیت، پلاستیک، فولاد و استیل | M33: دستگیره توپی گرد با سوراخ رزوه‌دار داخلی یا سوراخ ساده | N33: 21 | O33: دارد | P33: دارد | Q33: دارد
A34: 33 | B34: DIN | C34: DIN 404 | D34: پیچ دوسو سر کاپستان | E34: Slotted capstan screws | F34: پیچ دوسو و چهارسو | G34: 3 | H34: DIN 404 | I34: CSN 021128، UNI 6111 | J34: M2 – M10 | K34: 8 | L34: فولاد 5.8، استیل A2-70، استیل A4-70 | M34: پیچ پلمب دوسو، پیچ تنظیم | N34: 108 | O34: دارد | P34: دارد | Q34: دارد
A35: 34 | B35: DIN | C35: DIN 417 | D35: پیچ مغزی دوسو نوک پین | E35: Slotted set screws, long dog point | F35: پیچ مغزی | G35: 3 | H35: DIN EN 27435 | I35: ISO 7435، CSN 021183، PN 82276، EU 27435 | J35: M1.6 – M12 | K35: 11 | L35: فولاد 4.8، فولاد 5.8، استیل A2-70، استیل A4-70 | M35: پیچ مغزی دوسو نوک خلاصی | N35: 50 | O35: دارد | P35: دارد | Q35: دارد
A36: 35 | B36: DIN | C36: DIN 427 | D36: پیچ مغزی دوسو نوک تخت | E36: Slotted headless screws with flat point | F36: پیچ مغزی | G36: 3 | H36: DIN EN 2342 | I36: PN 82271 | J36: M3 – M10 | K36: 6 | L36: فولاد 4.8، فولاد 5.8، استیل A2-70، استیل A4-70 | M36: پیچ مغزی دوسو نیم رزوه | N36: 45 | O36: دارد | P36: دارد | Q36: دارد
A37: 36 | B37: DIN | C37: DIN 431 | D37: مهره لوله | E37: Hexagon pipe nuts | F37: مهره | G37: 2 | H37: DIN 431 | J37: G1/8 – G21/2 | K37: 19 | N37: 19 | O37: دارد | P37: دارد | Q37: دارد
A38: 37 | B38: DIN | C38: DIN 432 | D38: واشر زبانه‌دار خارجی | E38: Tab washers, external tab | F38: واشر | G38: 3 | I38: CSN 021753، PN 82011، UNI 6599 | J38: M3 – M36 | K38: 13 | L38: فولاد کربنی گالوانیزه، استیل A2، استیل A4 | M38: واشر قفلی زبانه‌دار بیرونی، واشر خم شونده مخصوص قفل کردن مهره | N38: 13 | O38: دارد | P38: دارد | Q38: دارد
A39: 38 | B39: DIN | C39: DIN 433 | D39: واشر تخت برای پیچ سر استوانه‌ای | E39: Washers for cheese head screws | F39: واشر | G39: 2 | H39: DIN EN ISO 7092 | I39: ISO 7092، CSN 021703، PN 82007، UNI 6592 | J39: M1 – M36 | K39: 22 | L39: فولاد کربنی گالوانیزه، استیل A2، استیل A4 | M39: واشر تخت باریک | N39: 22 | O39: دارد | P39: دارد | Q39: دارد
A40: 39 | B40: DIN | C40: DIN 434 | D40: واشر گوه‌ای چهارگوش برای ناودانی (U) | E40: Square taper washers for U-sections | F40: واشر | G40: 2 | H40: DIN 434 | I40: CSN 021739، PN 82018، UNI 6598 | J40: M8 – M27 | K40: 8 | L40: فولاد کربنی گالوانیزه، استیل A2، استیل A4 | M40: واشر ریلی دوشیار، واشر سیب‌دار مربعی مخصوص تیرآهن U، واشر گوه‌ای ناودانی با شیب8% | N40: 8 | O40: دارد | P40: دارد | Q40: دارد
...

Sheet خلاصه
A1: خلاصهٔ استانداردهای مخزن
A3: کل استانداردها | B3: =COUNTA('فهرست استانداردها'!C2:C351)
A4: DIN | B4: =COUNTIF('فهرست استانداردها'!B2:B351,"DIN")
A5: ASTM | B5: =COUNTIF('فهرست استانداردها'!B2:B351,"ASTM")
A6: اولویت ۱ (DIN) | B6: =COUNTIF('فهرست استانداردها'!G2:G351,1)
A7: اولویت ۲ (DIN) | B7: =COUNTIF('فهرست استانداردها'!G2:G351,2)
A8: اولویت ۳ (DIN) | B8: =COUNTIF('فهرست استانداردها'!G2:G351,3)
A9: بدون عکس محصول | B9: =COUNTIF('فهرست استانداردها'!O2:O351,"—")
A10: جمع کالاهای کددار | B10: =SUM('فهرست استانداردها'!N2:N351)
A12: تعداد به تفکیک دسته
A13: پین | B13: =COUNTIF('فهرست استانداردها'!F2:F351,A13)
A14: سایر اتصالات و یراق | B14: =COUNTIF('فهرست استانداردها'!F2:F351,A14)
A15: پیچ دوسو و چهارسو | B15: =COUNTIF('فهرست استانداردها'!F2:F351,A15)
A16: واشر | B16: =COUNTIF('فهرست استانداردها'!F2:F351,A16)
A17: پیچ خودکار، سرمته و چوب | B17: =COUNTIF('فهرست استانداردها'!F2:F351,A17)
A18: پیچ سرخاص و کالسکه | B18: =COUNTIF('فهرست استانداردها'!F2:F351,A18)
A19: مهره | B19: =COUNTIF('فهرست استانداردها'!F2:F351,A19)
A20: پیچ مغزی | B20: =COUNTIF('فهرست استانداردها'!F2:F351,A20)
A21: اتصالات بالابری و مهارکش | B21: =COUNTIF('فهرست استانداردها'!F2:F351,A21)
A22: خار | B22: =COUNTIF('فهرست استانداردها'!F2:F351,A22)
A23: استاد بولت و میل‌رزوه | B23: =COUNTIF('فهرست استانداردها'!F2:F351,A23)
A24: پیچ شش‌گوش | B24: =COUNTIF('فهرست استانداردها'!F2:F351,A24)
A25: پرچ | B25: =COUNTIF('فهرست استانداردها'!F2:F351,A25)
A26: پیچ آلن و تورکس | B26: =COUNTIF('فهرست استانداردها'!F2:F351,A26)
A27: مهره قفلی | B27: =COUNTIF('فهرست استانداردها'!F2:F351,A27)
A28: استاد بولت فلنج ASTM | B28: =COUNTIF('فهرست استانداردها'!F2:F351,A28)
A29: مهره ASTM | B29: =COUNTIF('فهرست استانداردها'!F2:F351,A29)
A30: پیچ شش‌گوش و آلن ASTM | B30: =COUNTIF('فهرست استانداردها'!F2:F351,A30)
A31: انکر بولت ASTM | B31: =COUNTIF('فهرست استانداردها'!F2:F351,A31)
A32: پیچ و مهرهٔ سازه‌ای ASTM | B32: =COUNTIF('فهرست استانداردها'!F2:F351,A32)
A33: واشر سازه‌ای ASTM | B33: =COUNTIF('فهرست استانداردها'!F2:F351,A33)
A35: منبع: دادهٔ نسخهٔ آخر پروتوتایپ کارما (پس از اعمال فایل اصلاحات). اولویت‌ها از فهرست DIN_P و فقط برای استفادهٔ داخلی است.
